Workbook
Name Slicer_Salesperson: #N/A

Sheet START_HERE
A1: Sales Analytics Dashboard — Excel Portfolio Project
A2: Excel Portfolio Project · Data Analysis & Visualization
A4: PROJECT OVERVIEW
A5: An Excel project analyzing 60 sales orders to understand completed revenue, city performance, salesperson performance, product performance, and order status.
A8: KEY RESULTS
A10: Total Orders | C10: Actual Revenue | E10: Completed Orders | G10: Actual AOV
A11: 60 | C11: ₹48,980.00 | E11: 34 | G11: ₹1,440.59
A13: WORKBOOK GUIDE
A14: 1.Dashboard
A15: View KPIs and charts.
A16: 2.Analysis
A17: Review formula-driven summaries and metrics.
A18: 3.Raw_Sales
A19: Inspect the 60 original order records and calculated fields.
A20: 4.Product_Master
A21: Look up product details and prices.
A22: 5.Pivot_table
A23: Explore Pivot Table summaries.
A25: Metric definition: Completed revenue includes only orders marked Completed. Total order value includes all statuses, including Pending and Cancelled.

Sheet Dashboard
C1: SALES ANALYTICS DASHBOARD
A3: Total Orders | C3: Actual Revenue | E3: Completed Orders | G3: Actual AOV
A4: =Analysis!B2 -> 60 | C4: =Analysis!B3 -> 48980 | E4: =Analysis!B4 -> 34 | G4: =Analysis!B5 -> 1440.5882

Sheet Analysis
A1: KPI
A2: Total Orders | B2: =COUNTA(Raw_Sales!A2:A61) -> 60
A3: Actual Revenue | B3: =SUMIFS(Raw_Sales!M2:M61,Raw_Sales!L2:L61,"Completed") -> 48980
A4: Completed Orders | B4: =COUNTIF(Raw_Sales!L2:L61,"Completed") -> 34
A5: Actual AOV | B5: =B3/B4 -> 1440.5882
A7: Revenue by City
A8: City | B8: Revenue
A9: Chennai | B9: =SUMIFS(Raw_Sales!M2:M61,Raw_Sales!G2:G61,A9,Raw_Sales!L2:L61,"Completed") -> 15950
A10: Coimbatore | B10: =SUMIFS(Raw_Sales!M2:M61,Raw_Sales!G2:G61,A10,Raw_Sales!L2:L61,"Completed") -> 19040
A11: Madurai | B11: =SUMIFS(Raw_Sales!M3:M62,Raw_Sales!G3:G62,A11,Raw_Sales!L3:L62,"Completed") -> 2140
A12: Trichy | B12: =SUMIFS(Raw_Sales!M4:M63,Raw_Sales!G4:G63,A12,Raw_Sales!L4:L63,"Completed") -> 11850
A14: Actual Revenue by Salesperson
A15: Salesperson | B15: Actual Revenue
A16: Priya | B16: =SUMIFS(Raw_Sales!M1:M61,Raw_Sales!H1:H61,A16,Raw_Sales!L1:L61,"Completed") -> 20680
A17: Arun | B17: =SUMIFS(Raw_Sales!M2:M61,Raw_Sales!H2:H61,A17,Raw_Sales!L2:L61,"Completed") -> 16150
A18: Karthik | B18: =SUMIFS(Raw_Sales!M2:M61,Raw_Sales!H2:H61,A18,Raw_Sales!L2:L61,"Completed") -> 9450
A19: Meena | B19: =SUMIFS(Raw_Sales!M2:M61,Raw_Sales!H2:H61,A19,Raw_Sales!L2:L61,"Completed") -> 2700
A22: Orders by Status
A23: Status | B23: Orders
A24: Completed | B24: =COUNTIF(Raw_Sales!$L$2:$L$61,A24) -> 34
A25: Pending | B25: =COUNTIF(Raw_Sales!$L$2:$L$61,A25) -> 14
A26: Cancelled | B26: =COUNTIF(Raw_Sales!$L$2:$L$61,A26) -> 12
A28: Revenue by Product
A29: Product
A30: Backpack | B30: =SUMIFS(Raw_Sales!$M$2:$M$61,Raw_Sales!$E$2:$E$61,A30,Raw_Sales!$L$2:$L$61,"Completed") -> 10800
A31: Calculator | B31: =SUMIFS(Raw_Sales!$M$2:$M$61,Raw_Sales!$E$2:$E$61,A31,Raw_Sales!$L$2:$L$61,"Completed") -> 6300
A32: Desk Lamp | B32: =SUMIFS(Raw_Sales!$M$2:$M$61,Raw_Sales!$E$2:$E$61,A32,Raw_Sales!$L$2:$L$61,"Completed") -> 18900
A33: Notebook | B33: =SUMIFS(Raw_Sales!$M$2:$M$61,Raw_Sales!$E$2:$E$61,A33,Raw_Sales!$L$2:$L$61,"Completed") -> 800
A34: Pen Set | B34: =SUMIFS(Raw_Sales!$M$2:$M$61,Raw_Sales!$E$2:$E$61,A34,Raw_Sales!$L$2:$L$61,"Completed") -> 750
A35: USB Cable | B35: =SUMIFS(Raw_Sales!$M$2:$M$61,Raw_Sales!$E$2:$E$61,A35,Raw_Sales!$L$2:$L$61,"Completed") -> 4680
A36: Water Bottle | B36: =SUMIFS(Raw_Sales!$M$2:$M$61,Raw_Sales!$E$2:$E$61,A36,Raw_Sales!$L$2:$L$61,"Completed") -> 3500
A37: Wireless Mouse | B37: =SUMIFS(Raw_Sales!$M$2:$M$61,Raw_Sales!$E$2:$E$61,A37,Raw_Sales!$L$2:$L$61,"Completed") -> 3250

Sheet Raw_Sales
A1: Order_ID | B1: Date | C1: Customer | D1: Product_ID | E1: Product | F1: Category | G1: City | H1: Salesperson | I1: Quantity | J1: Unit_Price | K1: Payment | L1: Status | M1: Revenue | N1: Order Level
A2: ORD047 | B2: 46252 | C2: Customer 10 | D2: P006 | E2: Desk Lamp | F2: Home | G2: Chennai | H2: Priya | I2: 5 | J2: 900 | K2: UPI | L2: Completed | M2: =I2 * J2 -> 4500 | N2: =IF(M2 >=2000,"high",IF(M2 >=1000,"medium","low")) -> high
A3: ORD023 | B3: 46249 | C3: Customer 34 | D3: P007 | E3: Backpack | F3: Bags | G3: Chennai | H3: Arun | I3: 3 | J3: 1200 | K3: UPI | L3: Completed | M3: =I3 * J3 -> 3600 | N3: =IF(M3 >=2000,"high",IF(M3 >=1000,"medium","low")) -> high
A4: ORD027 | B4: 46238 | C4: Customer 07 | D4: P007 | E4: Backpack | F4: Bags | G4: Chennai | H4: Karthik | I4: 2 | J4: 1200 | K4: Cash | L4: Pending | M4: =I4 * J4 -> 2400 | N4: =IF(M4 >=2000,"high",IF(M4 >=1000,"medium","low")) -> high
A5: ORD041 | B5: 46244 | C5: Customer 11 | D5: P004 | E5: Wireless Mouse | F5: Electronics | G5: Chennai | H5: Karthik | I5: 3 | J5: 650 | K5: Card | L5: Cancelled | M5: =I5 * J5 -> 1950 | N5: =IF(M5 >=2000,"high",IF(M5 >=1000,"medium","low")) -> medium
A6: ORD005 | B6: 46238 | C6: Customer 06 | D6: P004 | E6: Wireless Mouse | F6: Electronics | G6: Chennai | H6: Arun | I6: 3 | J6: 650 | K6: Cash | L6: Completed | M6: =I6 * J6 -> 1950 | N6: =IF(M6 >=2000,"high",IF(M6 >=1000,"medium","low")) -> medium
A7: ORD014 | B7: 46239 | C7: Customer 33 | D7: P006 | E7: Desk Lamp | F7: Home | G7: Chennai | H7: Arun | I7: 2 | J7: 900 | K7: UPI | L7: Completed | M7: =I7 * J7 -> 1800 | N7: =IF(M7 >=2000,"high",IF(M7 >=1000,"medium","low")) -> medium
A8: ORD030 | B8: 46242 | C8: Customer 05 | D8: P005 | E8: Water Bottle | F8: Home | G8: Chennai | H8: Arun | I8: 4 | J8: 350 | K8: UPI | L8: Cancelled | M8: =I8 * J8 -> 1400 | N8: =IF(M8 >=2000,"high",IF(M8 >=1000,"medium","low")) -> medium
A9: ORD033 | B9: 46244 | C9: Customer 28 | D9: P005 | E9: Water Bottle | F9: Home | G9: Chennai | H9: Priya | I9: 4 | J9: 350 | K9: UPI | L9: Completed | M9: =I9 * J9 -> 1400 | N9: =IF(M9 >=2000,"high",IF(M9 >=1000,"medium","low")) -> medium
A10: ORD050 | B10: 46240 | C10: Customer 22 | D10: P007 | E10: Backpack | F10: Bags | G10: Chennai | H10: Priya | I10: 1 | J10: 1200 | K10: Cash | L10: Completed | M10: =I10 * J10 -> 1200 | N10: =IF(M10 >=2000,"high",IF(M10 >=1000,"medium","low")) -> medium
A11: ORD060 | B11: 46253 | C11: Customer 20 | D11: P003 | E11: USB Cable | F11: Electronics | G11: Chennai | H11: Arun | I11: 5 | J11: 180 | K11: Cash | L11: Completed | M11: =I11 * J11 -> 900 | N11: =IF(M11 >=2000,"high",IF(M11 >=1000,"medium","low")) -> low
A12: ORD003 | B12: 46241 | C12: Customer 35 | D12: P001 | E12: Notebook | F12: Stationery | G12: Chennai | H12: Priya | I12: 5 | J12: 80 | K12: Cash | L12: Cancelled | M12: =I12 * J12 -> 400 | N12: =IF(M12 >=2000,"high",IF(M12 >=1000,"medium","low")) -> low
A13: ORD004 | B13: 46259 | C13: Customer 11 | D13: P005 | E13: Water Bottle | F13: Home | G13: Chennai | H13: Karthik | I13: 1 | J13: 350 | K13: Cash | L13: Completed | M13: =I13 * J13 -> 350 | N13: =IF(M13 >=2000,"high",IF(M13 >=1000,"medium","low")) -> low
... A61: ORD021 | B61: 46258 | C61: Customer 32 | D61: P002 | E61: Pen Set | F61: Stationery | G61: Trichy | H61: Priya | I61: 1 | J61: 50 | K61: UPI | L61: Pending | M61: =I61 * J61 -> 50 | N61: =IF(M61 >=2000,"high",IF(M61 >=1000,"medium","low")) -> low

Sheet Product_Master
A1: Product_ID | B1: Product | C1: Category | D1: Unit_Price
A2: P001 | B2: Notebook | C2: Stationery | D2: 80
A3: P002 | B3: Pen Set | C3: Stationery | D3: 50
A4: P003 | B4: USB Cable | C4: Electronics | D4: 180
A5: P004 | B5: Wireless Mouse | C5: Electronics | D5: 650
A6: P005 | B6: Water Bottle | C6: Home | D6: 350
A7: P006 | B7: Desk Lamp | C7: Home | D7: 900
A8: P007 | B8: Backpack | C8: Bags | D8: 1200
A9: P008 | B9: Calculator | C9: Electronics | D9: 450

Sheet Pivot_table
A2: Pivot 1 — Revenue by City
A3: City | B3: Sum of Revenue
A4: Chennai | B4: 22300
A5: Coimbatore | B5: 29350
A6: Madurai | B6: 11570
A7: Trichy | B7: 23610
A8: Grand Total | B8: 86830
A12: Pivot 2 — Orders by City & Status
A13: Count of Order_ID | B13: Status
A14: City | B14: Cancelled | C14: Completed | D14: Pending | E14: Grand Total
A15: Chennai | B15: 3 | C15: 10 | D15: 2 | E15: 15
A16: Coimbatore | B16: 2 | C16: 13 | D16: 6 | E16: 21
A17: Madurai | B17: 2 | C17: 4 | D17: 4 | E17: 10
A18: Trichy | B18: 5 | C18: 7 | D18: 2 | E18: 14
A19: Grand Total | B19: 12 | C19: 34 | D19: 14 | E19: 60
A21: Pivot 3 — Revenue by Salesperson
A22: Sum of Revenue | B22: Status
A23: Salesperson | B23: Cancelled | C23: Completed | D23: Pending | E23: Grand Total
A24: Arun | B24: 1550 | C24: 16150 | D24: 2150 | E24: 19850
A25: Karthik | B25: 11900 | C25: 9450 | D25: 6900 | E25: 28250
A26: Meena | B26: 5540 | C26: 2700 | D26: 5320 | E26: 13560
A27: Priya | B27: 400 | C27: 20680 | D27: 4090 | E27: 25170
A28: Grand Total | B28: 19390 | C28: 48980 | D28: 18460 | E28: 86830
A34: Pivot 4 - salesperson orders sold
A35: Salesperson | B35: Count of Order_ID | C35: Sum of Revenue
A36: Arun | B36: 15 | C36: 19850
A37: Karthik | B37: 14 | C37: 28250
A38: Meena | B38: 14 | C38: 13560
A39: Priya | B39: 17 | C39: 25170
A40: Grand Total | B40: 60 | C40: 86830
A42: Status | B42: Completed
A43: Pivot 5 - Actualy Revenue on completed
A44: Salesperson | B44: Sum of Revenue
A45: Arun | B45: 16150
A46: Karthik | B46: 9450
A47: Meena | B47: 2700
A48: Priya | B48: 20680
A49: Grand Total | B49: 48980
A52: Salesperson | B52: Priya
A53: Status | B53: Completed
...
